## 예외처리 - (2)

```
package yoon;

public class ExceptionMessage2 {
    public static void md1(int n) {
        md2(n, 0); // 이 지점으로 md2로부터 예외가 넘어온다
    }

    public static void md2(int n1, int n2) {
        int r = n1 / n2; // 이 지점에서 예외가 발생한다.
    }

    public static void main(String [] args) {
        try {
            md1(3);
        }
        catch (Throwable e) {
            e.printStackTrace();
        }
    }
}
//result
java.lang.ArithmeticException: / by zero
	at yoon.ExceptionMessage2.md2(ExceptionMessage2.java:9)
	at yoon.ExceptionMessage2.md1(ExceptionMessage2.java:5)
	at yoon.ExceptionMessage2.main(ExceptionMessage2.java:14)
    
```
- 실제로 넘어오는 예외는 Throwable이 아니다. 그러나 모든 예외클래스는 Throwable을 상속하므로 상속관계에 의해 md2에서 발생한예외를 처리할 수 있다.